Workbook

Sheet Model Explainer
A1: HealthDirect Simultaneous Interpreter: Model Architecture & Roles
A3: SECTION 1: OVERVIEW & STRATEGIC HIGHLIGHTS
A4: This workbook provides a rigorous, data-driven cost and performance model comparing three alternative deployment approaches for real-time translation on HealthDirect Video Call, as well as the new post-call clinical summary workflow. Model projections are based on official scale parameters (1.8 Million annual consultations, rounded 30-minute average, and 5% to 10% translation target).
A6: SECTION 2: MODEL ARCHITECTURE MATRIX
A7: Model / Approach | B7: Primary Role in System | C7: Pacing & Audio Streaming Profile | D7: Financial & Operational Implications
A8: Approach A: Native Translation Baseline (gemini-3.5-live-translate-preview) | B8: Handles real-time Patient-to-Nurse and Nurse-to-Patient simultaneous translation natively. Post-call summary dynamically uses gemini-3.5-flash to align model families. | C8: Hardware-accelerated native translation pacing. Summary is triggered as a single non-streaming unary text-to-text call immediately after session closure. | D8: RECOMMENDED BASELINE. Saves 7.5% to 8.5% on streaming costs. Dynamic post-call summarization adds only $0.00096 USD per session (0.14% overhead), fully integrated in totals.
A9: Approach B: Prompt-Driven Flash 3.1 (gemini-3.1-flash) | B9: Alternative translation approach where translation and pacing are guided via custom developer prompts. Post-call summary dynamically uses gemini-3.1-flash to align model families. | C9: Requires custom pacing prompts and manual turn buffers, adding a +12.5% duration overhead to streaming audio outputs. | D9: Incurs higher streaming and text fees due to the pacing expansion and prompt instruction size. Dynamic post-call summarization is fully integrated.
A10: Approach C: Prompt-Driven Flash 2.5 (gemini-2.5-flash) | B10: Legacy translation approach where translation and pacing are guided via legacy custom system instructions. Post-call summary dynamically uses gemini-2.5-flash to align model families. | C10: Requires identical custom pacing guidelines as Approach B, adding a +12.5% duration overhead to streaming audio outputs. | D10: Lowest unit text-token rate, but this minor saving is completely offset by high streaming rates. Dynamic post-call summarization is fully integrated.
A11: Clinical Summary Feature: Post-Call Summarization (Dynamic Family Mirroring) | B11: Compiles the completed session transcript and generates a structured clinical SOAP note / summary immediately after the call is finished. | C11: Dynamic family matching: Uses 3.5 Flash for Approach A, 3.1 Flash for Approach B, and 2.5 Flash for Approach C to maintain system-wide architectural consistency. | D11: Highly Cost-Efficient. Costs under 1/10th of a single cent per call across all model families, representing a minor 0.14% session cost overhead.

Sheet Cost Calculator
A1: HealthDirect Simultaneous Translation Cost Calculator
A3: SECTION 1: GLOBAL PARAMETERS
A4: Parameter | B4: Value | C4: Description
A5: AUD_USD_Exchange_Rate | B5: 1.515 | C5: Indicative exchange rate (1 USD = 1.515 AUD)
A6: Average_Session_Duration_Minutes | B6: 30 | C6: Adjustable production clinical session length in minutes (rounded to 30 mins)
A7: Annual_Total_Call_Volume | B7: 1800000 | C7: HealthDirect FY Video Call total consultation scale
A8: Target_Translation_Percentage | B8: 0.05 | C8: Estimated percentage of total call volume benefiting from translation (Low: 5%, High: 10%)
A9: Weeks_Per_Year | B9: 52 | C9: Standard billing weeks per calendar year
A10: Active_Speech_Duty_Cycle | B10: 0.4 | C10: Estimated percentage per channel of active speech (microphones only stream when active)
A11: Barge_In_Overlap_Overhead | B11: 0.05 | C11: Estimated streaming & playback duration overhead to account for overlap and barge-in
A12: Weekly_Session_Volume | B12: =B7*B8/B9 | C12: Dynamic weekly session volume: (Annual Volume * Target Rate) / Weeks Per Year
A14: SECTION 2: MODEL UNIT RATES (USD per Million Tokens)
A15: Service/Item | B15: gemini-3.5-live-translate-preview | C15: gemini-3.1-flash | D15: gemini-2.5-flash | E15: Unit
A16: Audio Input | B16: 3 | C16: 3 | D16: 3 | E16: per Million Tokens
A17: Audio Output | B17: 12 | C17: 12 | D17: 12 | E17: per Million Tokens
A18: Text Input | B18: 0.75 | C18: 0.75 | D18: 0.075 | E18: per Million Tokens
A19: Text Output | B19: 4.5 | C19: 4.5 | D19: 0.3 | E19: per Million Tokens
A20: Cached Read | B20: 0.15 | C20: 0.15 | D20: 0.015 | E20: per Million Tokens
A21: Cache Storage | B21: 1 | C21: 1 | D21: 0.1 | E21: per Million Tokens
A23: SECTION 3: EMPIRICAL BASES & FORMULAS (PER SESSION)
A24: Metric/Calculation | B24: Approach A: Native 3.5 | C24: Approach B: 3.1 Flash Prompt-driven | D24: Approach C: 2.5 Flash Prompt-driven | E24: Formula Description
A25: Prompt Cache Read Size (Tokens) | B25: 1000 | C25: 3000 | D25: 3000 | E25: Static instructions + glossary context
A26: Prompt Cache Read Cost (USD) | B26: =B25*(B20/1000000) | C26: =C25*(C20/1000000) | D26: =D25*(D20/1000000) | E26: Tokens * (Cache Read Rate / 1,000,000)
A27: Audio Input Tokens per Session | B27: =2*$B$6*60*250*$B$10*(1+$B$11) | C27: =2*$B$6*60*250*$B$10*(1+$B$11) | D27: =2*$B$6*60*250*$B$10*(1+$B$11) | E27: 2 connections * Duration in seconds * 250 tokens/sec * Duty Cycle * (1 + Overlap Overhead)
A28: Audio Input Cost (USD) | B28: =B27*(B16/1000000) | C28: =C27*(C16/1000000) | D28: =D27*(D16/1000000) | E28: Tokens * (Audio Input Rate / 1,000,000)
A29: Spoken Dialogue Word Count (Est.) | B29: =$B$6*$B$10*150 | C29: =$B$6*$B$10*150 | D29: =$B$6*$B$10*150 | E29: Duration * Active Duty Cycle * 150 words/min average speaking pace
A30: Audio Output Pacing Duration (Sec) | B30: =(B29/2.5)*(1+$B$11) | C30: =(C29/2.5)*1.125*(1+$B$11) | D30: =(D29/2.5)*1.125*(1+$B$11) | E30: Words / 2.5 words/sec * Pacing modifier * (1 + Overlap Overhead)
A31: Audio Output Tokens per Session | B31: =B30*250 | C31: =C30*250 | D31: =D30*250 | E31: Spoken seconds * 250 tokens/sec
A32: Audio Output Cost (USD) | B32: =B31*(B17/1000000) | C32: =C31*(C17/1000000) | D32: =D31*(D17/1000000) | E32: Tokens * (Audio Output Rate / 1,000,000)
A33: Transcription Text Output (Tokens) | B33: =(B29*2.2)*1.33 | C33: =(C29*2.2)*1.33 | D33: =(D29*2.2)*1.33 | E33: (Spoken + Translated words) * 1.33 tokens/word
A34: Transcription Text Cost (USD) | B34: =B33*(B19/1000000) | C34: =C33*(C19/1000000) | D34: =D33*(D19/1000000) | E34: Tokens * (Text Output Rate / 1,000,000)
A35: Post-Call Summary Input (Tokens) | B35: =B33 | C35: =C33 | D35: =D33 | E35: Input size of the compiled transcript text (matched to Row 33)
A36: Post-Call Summary Output (Tokens) | B36: 1200 | C36: 1200 | D36: 1200 | E36: Output size of the generated structured clinical SOAP note
A37: Post-Call Summary Cost (USD) | B37: =(B35*(B18/1000000))+(B36*(B19/1000000)) | C37: =(C35*(C18/1000000))+(C36*(C19/1000000)) | D37: =(D35*(D18/1000000))+(D36*(D19/1000000)) | E37: Summary (Input*InputRate + Output*OutputRate) / 1,000,000
A38: Total Session Cost (USD) | B38: =B26+B28+B32+B34+B37 | C38: =C26+C28+C32+C34+C37 | D38: =D26+D28+D32+D34+D37 | E38: Sum of all live streaming & summary costs
A39: Total Session Cost (AUD) | B39: =B38*$B$5 | C39: =C38*$B$5 | D39: =D38*$B$5 | E39: USD Cost * Exchange Rate
A41: SECTION 4: VOLUME PROJECTION CALCULATOR
A42: Volume / Projections | B42: Approach A: Native 3.5 | C42: Approach B: 3.1 Flash Prompt-driven | D42: Approach C: 2.5 Flash Prompt-driven | E42: Notes
A43: Weekly Cost (USD) | B43: =B38*$B$12 | C43: =C38*$B$12 | D43: =D38*$B$12 | E43: Sessions/Week * Session Cost (Row 38)
A44: Weekly Cost (AUD) | B44: =B43*$B$5 | C44: =C43*$B$5 | D44: =D43*$B$5 | E44: Weekly USD * Exchange Rate
...

Sheet Glossary Management
A1: HealthDirect Clinical Glossary Generator & Management
A3: SECTION 1: GLOSSARY GENERATION PARAMETERS
A4: Parameter | B4: Value | C4: Description
A5: Number_of_Active_Languages | B5: 5 | C5: Number of localized language dialects (Spanish, Arabic, Vietnamese, Hindi, Cantonese)
A6: Glossary_Master_Term_Count | B6: 500 | C6: Number of standardized medical terms and phrases to translate for the session prompt context
A7: Input_Tokens_Per_Term | B7: 25 | C7: Average input tokens per term (source word + translation instructions + context guidelines)
A8: Output_Tokens_Per_Term | B8: 50 | C8: Average output tokens per term (translated word + pronunciation phonetics + contextual note)
A9: Model_Input_Rate_Per_Million | B9: 1.25 | C9: Unit cost rate of Gemini 1.5 Pro to generate high-quality clinical translations (USD / Million)
A10: Model_Output_Rate_Per_Million | B10: 5 | C10: Unit cost rate of Gemini 1.5 Pro to generate high-quality clinical translations (USD / Million)
A12: SECTION 2: ONE-TIME GLOSSARY CREATION COST (GEMINI 1.5 PRO)
A13: Calculation Metric | B13: Value | C13: Formula Description
A14: Total Generation Input Tokens | B14: =B6*B7*B5 | C14: Master Term Count (B6) * Input Tokens (B7) * Languages (B5)
A15: Total Generation Output Tokens | B15: =B6*B8*B5 | C15: Master Term Count (B6) * Output Tokens (B8) * Languages (B5)
A16: Input Translation Cost (USD) | B16: =B14*(B9/1000000) | C16: Total Input Tokens * (Model Input Rate / 1,000,000)
A17: Output Translation Cost (USD) | B17: =B15*(B10/1000000) | C17: Total Output Tokens * (Model Output Rate / 1,000,000)
A18: Total One-Time Cost (USD) | B18: =B16+B17 | C18: Sum of input and output translation costs
A19: Total One-Time Cost (AUD) | B19: =B18*'Cost Calculator'!$B$5 | C19: Total USD Cost * Indicative Exchange Rate (Cost Calculator B5)
A21: SECTION 3: ANNUAL CLINICAL MAINTENANCE (50 TERMS ADDED/UPDATED)
A22: Maintenance Metric | B22: Value | C22: Formula Description
A23: Annual_New_Term_Maintenance | B23: 50 | C23: Average number of new clinical concepts/acronyms/guidelines added annually
A24: Maintenance Input Tokens (Annual) | B24: =B23*B7*B5 | C24: New Terms (B23) * Input Tokens (B7) * Languages (B5)
A25: Maintenance Output Tokens (Annual) | B25: =B23*B8*B5 | C25: New Terms (B23) * Output Tokens (B8) * Languages (B5)
A26: Annual Maintenance Cost (USD) | B26: =(B24*(B9/1000000))+(B25*(B10/1000000)) | C26: Annual (InputTokens*InputRate + OutputTokens*OutputRate) / 1,000,000
A27: Annual Maintenance Cost (AUD) | B27: =B26*'Cost Calculator'!$B$5 | C27: Annual USD Cost * Indicative Exchange Rate (Cost Calculator B5)
A29: SECTION 4: REAL-TIME CONTEXT CACHING INTEGRATION (PROMPT CACHING)
A30: Caching Parameter | B30: Value | C30: Formula Description
A31: Glossary Size in Session Cache (Tokens) | B31: =B6*B8 | C31: Glossary size per language: Master Term Count (B6) * Output Tokens (B8)
A32: Cache TTL / Inactivity Expiry (Hours) | B32: 1 | C32: Prompt Cache storage TTL: cached context is retained for 1 hour from last read
A33: Prompt Cache Storage Cost per Hour (USD) | B33: =B31*('Cost Calculator'!B21/1000000) | C33: Total Cached Tokens * (Cost Calculator Cache Storage Rate B21 / 1,000,000)
A34: Prompt Cache Storage Cost per Hour (AUD) | B34: =B33*'Cost Calculator'!$B$5 | C34: Cache Storage USD * Indicative Exchange Rate (Cost Calculator B5)
A35: Active Call Prompt Cache Read Savings (AUD) | B35: =(3000-B31)*('Cost Calculator'!B20/1000000)*'Cost Calculator'!$B$5 | C35: Saves up to $2.20 AUD per hour by avoiding uncached text reads across sessions
